INFO:config:原始DATABASE_URL: postgresql://nijie@localhost:5432/pma_local
INFO:app:数据库表创建成功
INFO:app.utils.version_check:版本信息已保存到 app_version.json
INFO:app.utils.version_check:模块 user 代码一致
INFO:app.utils.version_check:模块 customer 代码一致
INFO:app.utils.version_check:模块 project 代码一致
INFO:app.utils.version_check:模块 quotation 代码一致
INFO:app.utils.version_check:模块 product 代码一致
INFO:app:应用版本检查完成
INFO:app:数据所有权初始化已被关闭
INFO:app:字典数据初始化已被关闭
INFO:__main__:启动应用于端口 8082
数据库连接测试成功!
 * Serving Flask app 'app'
 * Debug mode: on
INFO:werkzeug:[31m[1mWARNING: This is a development server. Do not use it in a production deployment. Use a production WSGI server instead.[0m
 * Running on all addresses (0.0.0.0)
 * Running on http://127.0.0.1:8082
 * Running on http://192.168.1.174:8082
INFO:werkzeug:[33mPress CTRL+C to quit[0m
INFO:werkzeug: * Restarting with stat
INFO:config:原始DATABASE_URL: postgresql://nijie@localhost:5432/pma_local
INFO:app:数据库表创建成功
INFO:app.utils.version_check:版本信息已保存到 app_version.json
INFO:app.utils.version_check:模块 user 代码一致
INFO:app.utils.version_check:模块 customer 代码一致
INFO:app.utils.version_check:模块 project 代码一致
INFO:app.utils.version_check:模块 quotation 代码一致
INFO:app.utils.version_check:模块 product 代码一致
INFO:app:应用版本检查完成
INFO:app:数据所有权初始化已被关闭
INFO:app:字典数据初始化已被关闭
WARNING:werkzeug: * Debugger is active!
INFO:werkzeug: * Debugger PIN: 145-016-517
数据库连接测试成功!
Traceback (most recent call last):
  File "/Users/nijie/Documents/PMA/run.py", line 74, in <module>
    main()
    ~~~~^^
  File "/Users/nijie/Documents/PMA/run.py", line 52, in main
    app.run(
    ~~~~~~~^
        host='0.0.0.0',
        ^^^^^^^^^^^^^^^
        port=PORT,
        ^^^^^^^^^^
        debug=True
        ^^^^^^^^^^
    )
    ^
  File "/Users/nijie/Documents/PMA/venv312/lib/python3.13/site-packages/flask/app.py", line 662, in run
    run_simple(t.cast(str, host), port, self, **options)
    ~~~~~~~~~~^^^^^^^^^^^^^^^^^^^^^^^^^^^^^^^^^^^^^^^^^^
  File "/Users/nijie/Documents/PMA/venv312/lib/python3.13/site-packages/werkzeug/serving.py", line 1115, in run_simple
    run_with_reloader(
    ~~~~~~~~~~~~~~~~~^
        srv.serve_forever,
        ^^^^^^^^^^^^^^^^^^
    ...<3 lines>...
        reloader_type=reloader_type,
        ^^^^^^^^^^^^^^^^^^^^^^^^^^^^
    )
    ^
  File "/Users/nijie/Documents/PMA/venv312/lib/python3.13/site-packages/werkzeug/_reloader.py", line 459, in run_with_reloader
    ensure_echo_on()
    ~~~~~~~~~~~~~~^^
  File "/Users/nijie/Documents/PMA/venv312/lib/python3.13/site-packages/werkzeug/_reloader.py", line 439, in ensure_echo_on
    termios.tcsetattr(sys.stdin, termios.TCSANOW, attributes)
    ~~~~~~~~~~~~~~~~~^^^^^^^^^^^^^^^^^^^^^^^^^^^^^^^^^^^^^^^^
termios.error: (4, 'Interrupted system call')
Fatal Python error: init_sys_streams: can't initialize sys standard streams
Python runtime state: core initialized
OSError: [Errno 9] Bad file descriptor

Current thread 0x00000001f4345cc0 (most recent call first):
  <no Python frame>
